<?xml version="1.0" encoding="utf-8"?>
<!-- This URDF was automatically created by SolidWorks to URDF Exporter! Originally created by Stephen Brawner (brawner@gmail.com) 
     Commit Version: 1.6.0-1-g15f4949  Build Version: 1.6.7594.29634
     For more information, please see http://wiki.ros.org/sw_urdf_exporter -->
<robot
  name="robot_files">
  <link
    name="base_link">
    <inertial>
      <origin
        xyz="0.000918722169914224 0.00343955832859566 -0.0594339676459208"
        rpy="0 0 0" />
      <mass
        value="0.607299787326349" />
      <inertia
        ixx="0.00409895445744859"
        ixy="-4.29420289339434E-05"
        ixz="8.53173065999497E-06"
        iyy="0.00612240008379075"
        iyz="7.28635414394287E-05"
        izz="0.00721956172445048" />
    </inertial>
    <visual>
      <origin
        xyz="0 0 0"
        rpy="0 0 0" />
      <geometry>
        <mesh
          filename="package://robot_files/meshes/base_link.STL" />
      </geometry>
      <material
        name="">
        <color
          rgba="0.501960784313725 0 0 1" />
      </material>
    </visual>
    <collision>
      <origin
        xyz="0 0 0"
        rpy="0 0 0" />
      <geometry>
        <mesh
          filename="package://robot_files/meshes/base_link.STL" />
      </geometry>
    </collision>
  </link>
  <link
    name="Left_Wing">
    <inertial>
      <origin
        xyz="1.13718792299489E-08 0.020941352056886 0.0135367772048516"
        rpy="0 0 0" />
      <mass
        value="0.0170525154200708" />
      <inertia
        ixx="8.41258872248524E-06"
        ixy="-6.83074668451771E-12"
        ixz="1.6358666650079E-12"
        iyy="1.10862246332279E-06"
        iyz="-9.07733203595842E-07"
        izz="8.53994085230851E-06" />
    </inertial>
    <visual>
      <origin
        xyz="0 0 0"
        rpy="0 0 0" />
      <geometry>
        <mesh
          filename="package://robot_files/meshes/Left_Wing.STL" />
      </geometry>
      <material
        name="">
        <color
          rgba="0.250980392156863 0.250980392156863 0.250980392156863 1" />
      </material>
    </visual>
    <collision>
      <origin
        xyz="0 0 0"
        rpy="0 0 0" />
      <geometry>
        <mesh
          filename="package://robot_files/meshes/Left_Wing.STL" />
      </geometry>
    </collision>
  </link>
  <joint
    name="Left_Shoulder"
    type="continuous">
    <origin
      xyz="-0.057 0 0"
      rpy="3.14159265358979 0 -3.14147418503337" />
    <parent
      link="base_link" />
    <child
      link="Left_Wing" />
    <axis
      xyz="0 0 -1" />
  </joint>
  <link
    name="Left_Arm">
    <inertial>
      <origin
        xyz="0.00383979636023131 0.0357478681682257 0.0410237274937738"
        rpy="0 0 0" />
      <mass
        value="0.0516413964304408" />
      <inertia
        ixx="2.04415960512838E-05"
        ixy="3.85757381148507E-07"
        ixz="-9.81457271985976E-07"
        iyy="8.467046391812E-06"
        iyz="-1.48946395606745E-06"
        izz="1.87654290799313E-05" />
    </inertial>
    <visual>
      <origin
        xyz="0 0 0"
        rpy="0 0 0" />
      <geometry>
        <mesh
          filename="package://robot_files/meshes/Left_Arm.STL" />
      </geometry>
      <material
        name="">
        <color
          rgba="0.250980392156863 0.250980392156863 0.250980392156863 1" />
      </material>
    </visual>
    <collision>
      <origin
        xyz="0 0 0"
        rpy="0 0 0" />
      <geometry>
        <mesh
          filename="package://robot_files/meshes/Left_Arm.STL" />
      </geometry>
    </collision>
  </link>
  <joint
    name="Left_Elbow"
    type="continuous">
    <origin
      xyz="0 0.06 0.0218"
      rpy="0 0 0" />
    <parent
      link="Left_Wing" />
    <child
      link="Left_Arm" />
    <axis
      xyz="0 0 1" />
  </joint>
  <link
    name="Pusher">
    <inertial>
      <origin
        xyz="7.90079900270246E-06 1.46679547617656E-06 -0.0118921489197418"
        rpy="0 0 0" />
      <mass
        value="0.00327033697743112" />
      <inertia
        ixx="6.52897420453014E-07"
        ixy="-9.12919106345013E-14"
        ixz="7.80453279116826E-10"
        iyy="6.55134699818868E-07"
        iyz="8.54736636036147E-11"
        izz="1.46790811342743E-07" />
    </inertial>
    <visual>
      <origin
        xyz="0 0 0"
        rpy="0 0 0" />
      <geometry>
        <mesh
          filename="package://robot_files/meshes/Pusher.STL" />
      </geometry>
      <material
        name="">
        <color
          rgba="0.501960784313725 0 0 1" />
      </material>
    </visual>
    <collision>
      <origin
        xyz="0 0 0"
        rpy="0 0 0" />
      <geometry>
        <mesh
          filename="package://robot_files/meshes/Pusher.STL" />
      </geometry>
    </collision>
  </link>
  <joint
    name="Pusher_Linear_Joint"
    type="prismatic">
    <origin
      xyz="0.001599 0.06201 0.080314"
      rpy="0 0 3.1416" />
    <parent
      link="Left_Arm" />
    <child
      link="Pusher" />
    <axis
      xyz="0 0 1" />
    <limit
      lower="0"
      upper="0.01"
      effort="0"
      velocity="0" />
  </joint>
  <link
    name="Right_Wing">
    <inertial>
      <origin
        xyz="-1.1903859009621E-09 0.0174283238330747 0.0210758473943455"
        rpy="0 0 0" />
      <mass
        value="0.0205159397398244" />
      <inertia
        ixx="1.1020262167311E-05"
        ixy="-7.3841319479749E-12"
        ixz="-2.9639554363113E-12"
        iyy="2.45362903468534E-06"
        iyz="-2.14049470008707E-06"
        izz="1.0086406628157E-05" />
    </inertial>
    <visual>
      <origin
        xyz="0 0 0"
        rpy="0 0 0" />
      <geometry>
        <mesh
          filename="package://robot_files/meshes/Right_Wing.STL" />
      </geometry>
      <material
        name="">
        <color
          rgba="0.250980392156863 0.250980392156863 0.250980392156863 1" />
      </material>
    </visual>
    <collision>
      <origin
        xyz="0 0 0"
        rpy="0 0 0" />
      <geometry>
        <mesh
          filename="package://robot_files/meshes/Right_Wing.STL" />
      </geometry>
    </collision>
  </link>
  <joint
    name="Right_Shoulder"
    type="continuous">
    <origin
      xyz="0.057 0 0"
      rpy="3.14159265358979 0 3.14123293721384" />
    <parent
      link="base_link" />
    <child
      link="Right_Wing" />
    <axis
      xyz="0 0 1" />
  </joint>
  <link
    name="Right_Arm">
    <inertial>
      <origin
        xyz="0.000899898154557391 0.0269819162539917 0.00457404795047582"
        rpy="0 0 0" />
      <mass
        value="0.00787461829731969" />
      <inertia
        ixx="2.99705129724147E-06"
        ixy="-9.42935964090507E-08"
        ixz="-3.1970563468735E-10"
        iyy="1.72965417241279E-07"
        iyz="-9.58641568161662E-09"
        izz="3.07401564500097E-06" />
    </inertial>
    <visual>
      <origin
        xyz="0 0 0"
        rpy="0 0 0" />
      <geometry>
        <mesh
          filename="package://robot_files/meshes/Right_Arm.STL" />
      </geometry>
      <material
        name="">
        <color
          rgba="0.250980392156863 0.250980392156863 0.250980392156863 1" />
      </material>
    </visual>
    <collision>
      <origin
        xyz="0 0 0"
        rpy="0 0 0" />
      <geometry>
        <mesh
          filename="package://robot_files/meshes/Right_Arm.STL" />
      </geometry>
    </collision>
  </link>
  <joint
    name="Right_Elbow"
    type="continuous">
    <origin
      xyz="0 0.0599999999999979 0.0327999999999994"
      rpy="0 0 0" />
    <parent
      link="Right_Wing" />
    <child
      link="Right_Arm" />
    <axis
      xyz="0 0 -1" />
  </joint>
</robot>
